<h1>Structured Concurrency</h1>

<p>Мы уже отменяли <code>Job</code> (корутину). Отменять и очищать код полезно и нужно, чтобы не занимать ресурсы и не плодить утечки памяти. Архитектура корутин составлена таким образом, что, по умолчанию, отмена любой джобы останавливает все дочерние джобы. Однако, отмена корутины не всегда гарантирует остановку корутины. Рассмотрим такой код:</p>

<pre><code>fun main(args: Array&lt;String&gt;): Unit = runBlocking {
    val job = launch(Dispatchers.IO) {
        while (true) {
            println("We are inside coroutine")
        }
    }

    delay(50L)
    job.cancel()
}</code></pre>

<p>Хотя мы и вызываем сразу <strong>cancel()</strong> для <code>Job</code>, она по факту не остановит <code>Job</code>, а выставит некий флаг внутри корутины (isCancelled = true). И далее делается проверка <strong>isActive(),</strong> чтобы понимать нужно ли завершить работу корутины. Такая проверка происходит неявным образом перед созданием новой дочерней корутины, либо перед и после вызова другой <u>suspend функции</u>. </p>

<p>В нашем примере нет новый корутин и вызова внешних <strong>suspend</strong> функций, поэтому нам нужно самим проверять состояние джобы:</p>

<pre><code>fun main(args: Array&lt;String&gt;): Unit = runBlocking {
    val job = launch(Dispatchers.IO) {
        while (true) {
            if (!isActive) {
                println("Ok, now I shut up")
                return@launch
            }
            println("We are inside coroutine")
        }
    }

    delay(50L)
    job.cancel()
}</code></pre>

<p>При отмене корутина вызывает <code>CancellationException</code>. Это важный момент, так как именно этот тип исключение и позволяет останавливать родительские корутины: </p>

<pre><code>fun main() = runBlocking {
    val job = launch(Dispatchers.Default) {
        repeat(5) { i -&gt;
            try {
                // print a message twice a second
                println("job: I'm sleeping $i ...")
                delay(500)
            } catch (e: Exception) {
                // log the exception
                println(e)
            }
        }
    }
    delay(1300L) // delay a bit
    println("main: I'm tired of waiting!")
    job.cancelAndJoin() // cancels the job and waits for its completion
    println("main: Now I can quit.")
}</code></pre>

<p>В этом примере <strong>job</strong> останавливается при <strong>job.cancelAndJoin</strong>, однако <strong>job</strong> не остановится, так как мы отловили этот exception. <code>CancellationException</code> не пробросился вверх и родительская корутина не остановится. Для корректной остановки, нужно пробросить обработку этого exception:</p>

<pre><code>fun main() = runBlocking {
    val job = launch(Dispatchers.Default) {
        repeat(5) { i -&gt;
            try {
                // print a message twice a second
                println("job: I'm sleeping $i ...")
                delay(500)
            } catch (e: CancellationException) {
                throw e
            } catch (e: Exception) {
                println(e)
            }
        }
    }
    delay(1300L) // delay a bit
    println("main: I'm tired of waiting!")
    job.cancelAndJoin() // cancels the job and waits for its completion
    println("main: Now I can quit.")
}</code></pre>




<h1>Exception Handling</h1>

<p>В асинхронном мире выброс исключения может произойти в неожиданных местах. Работая с <code>launch{}</code> билдером, выброс exception прекращает <strong>job</strong>, что также прекращает все дочерние и родительскую job. Прекращение родительской корутины рекурсивно прекращает все ее дочерние и родительские корутины. В итоге все корутины завершат свою работу. </p>

<pre><code>fun main() = runBlocking {
    val launchJob = GlobalScope.launch {
        println("1. Exception created via launch coroutine")
        throw IndexOutOfBoundsException()
    }
    launchJob.join()
    println("2. Joined failed job")
    val deferred = GlobalScope.async {
        println("3. Exception created via async coroutine")
        throw ArithmeticException()
    }
    try {
        deferred.await()
        println("4. Unreachable, this statement is never executed")
    } catch (e: Exception) {
        println("5. Caught ${e.javaClass.simpleName}")
    }
}</code></pre>

<p>Вывод: </p>

<pre><code>1. Exception created via launch coroutine
2. Joined failed job
3. Exception created via async coroutine
5. Caught ArithmeticException
Exception in thread "DefaultDispatcher-worker-2" java.lang</code></pre>

<p>Как видно из логов,  <code>IndexOutOfBoundsException</code> не остановил все корутины. Это потому что эта корутина была запущена в другом (<code>GlobalScope</code>) скоупе. Попробуйте убрать <code>GlobalScope</code> и посмотреть вывод.</p>

<p>Далее при <code>await()</code> у нас произошло исключение, так как корутина выбросила его. При этом в самом async билдера ничего не останавливается, так билдер нужно запустить с помощью <code>await()</code>.  Строчка   <code>println("4. Unreachable, this statement is never executed")</code> так и. не вызвалась из-за прыжка в блок catch. Об этом даже IDE предупреждает перед запуском кода.</p>

<p>Нужно отметить, что при <strong>launch{}</strong> обработать ошибки нужно в <u>рамках самой корутины</u>, а при <strong>async{}</strong> - <u>вне корутины</u>. Обработка исключений является ответственностью разработчика.</p>



<h1>CoroutineExceptionHandler</h1>

<p>Теперь рассмотрим такой код:</p>

<pre><code>fun main() {
    runBlocking {
        val exceptionHandler = CoroutineExceptionHandler { _, exception -&gt;
            println("Caught $exception")
        }
        val job = GlobalScope.launch(exceptionHandler) {
            println("job")
            throw AssertionError("My Custom Assertion Error!")
        }
        val job2 = GlobalScope.launch(exceptionHandler) {
            println("job2")
            throw AssertionError("My Custom Assertion Error!")
        }
        val deferred = async(exceptionHandler) {
            throw ArithmeticException()
        }
        joinAll(job, job2, deferred)
    }
}</code></pre>

<p><code>ExceptionHandler</code> является частью <code>CoroutineContext</code> и позволяет отловить исключения внутри заданной корутины и всех ее дочерних корутин. Важно отметить, что он не является <u>обработчиком исключений</u> корутины, так как exception-ы все равно <strong>пойдут вверх по иерархии</strong>, но мы можем таким образом написать свою логику прежде, чем это случится. Обычно там логируются исключения.  </p>

<p>В примере выше также родительская корутина не остановилась из-за глобального скоупа. Попробуйте убрать и посмотреть как поведет себя код. Можете проверить на каком потоке запускается скоуп с помощью метода </p>

<pre><code>Thread.currentThread()</code></pre>

<p>Ваша программа упадет только в том случае, если было исключение на main потоке, а используя <code>GlobalScope.launch()/GlobalScope.async()</code> без явного указания <code>Dispatchers.Main</code>, у вас корутина будет выполняться (и выбрасывать исключения) в другом потоке, поэтому ваша программа продолжает работать, хоть и выведет само исключение на консоль.</p>



<h1>SupervisorJob</h1>

<p>В прошлых примерах при выбросе исключения из корутины происходит остановка всех корутин. Однако, такое поведение отличается для <code>GlobalScope</code>. На самом деле использование <code>GlobalScope</code> является <strong>антипаттерном</strong>. Оно нарушает всю идею Structured Concurrency. Рекомендую к прочтению <a href="https://elizarov.medium.com/the-reason-to-avoid-globalscope-835337445abc" rel="noopener noreferrer nofollow">статью</a>.</p>

<p>Итак, при выбросе exception <strong>launch()</strong> останавливает себя и передает исключение для обработки родительской корутине. В итоге исключение в одной из дочерних корутин останавливает все дочерние корутины. Если такое поведение не желательно, используйте <code>SupervisorJob</code>:</p>

<pre><code>fun main() = runBlocking {
    val supervisorJob = SupervisorJob()
    val coroutineScope = CoroutineScope(coroutineContext + supervisorJob)
    val firstChild: Job = coroutineScope.launch {
        println("First child throwing an exception")
        throw ArithmeticException()
    }
    val secondChild: Job = coroutineScope.launch {
        println("First child is cancelled: ${firstChild.isCancelled}")
        try {
            delay(5000)
        } catch (e: CancellationException) {
            println("Second child cancelled because supervisor got cancelled.")
        }
    }
    firstChild.join()
    println("Second child is active: ${secondChild.isActive}")
    supervisorJob.cancel()
    secondChild.join()
}</code></pre>

<p>Здесь мы создали новую <code>Job</code>, которая наследует контекст из вызывающей корутины, но переопределяет <code>Job</code> своим <code>SupervisorJob</code>. Можете запустить и заметить, что падение <strong>firstChild</strong> не останавливает <strong>secondChild</strong>. Однако <strong>secondChild</strong> остановится при вызове <strong>сancel()</strong> у  <code>SupervisorJob</code>.  </p>

<p>Также в примере выше мы создали свой скоуп (отличный от GlobalScope), о котором мы поговорим в следующем разделе.</p>